[2022-11-12T11:51:42.979+0000] {taskinstance.py:1165} INFO - Dependencies all met for <TaskInstance: load_to_dwh_v2.load_raw_data manual__2022-11-12T11:51:30.115005+00:00 [queued]>
[2022-11-12T11:51:42.995+0000] {taskinstance.py:1165} INFO - Dependencies all met for <TaskInstance: load_to_dwh_v2.load_raw_data manual__2022-11-12T11:51:30.115005+00:00 [queued]>
[2022-11-12T11:51:42.995+0000] {taskinstance.py:1362} INFO - 
--------------------------------------------------------------------------------
[2022-11-12T11:51:42.995+0000] {taskinstance.py:1363} INFO - Starting attempt 1 of 6
[2022-11-12T11:51:42.995+0000] {taskinstance.py:1364} INFO - 
--------------------------------------------------------------------------------
[2022-11-12T11:51:43.019+0000] {taskinstance.py:1383} INFO - Executing <Task(PythonOperator): load_raw_data> on 2022-11-12 11:51:30.115005+00:00
[2022-11-12T11:51:43.025+0000] {standard_task_runner.py:54} INFO - Started process 419 to run task
[2022-11-12T11:51:43.029+0000] {standard_task_runner.py:82} INFO - Running: ['***', 'tasks', 'run', 'load_to_dwh_v2', 'load_raw_data', 'manual__2022-11-12T11:51:30.115005+00:00', '--job-id', '211', '--raw', '--subdir', 'DAGS_FOLDER/postgre_create_table.py', '--cfg-path', '/tmp/tmpkw_braz6']
[2022-11-12T11:51:43.030+0000] {standard_task_runner.py:83} INFO - Job 211: Subtask load_raw_data
[2022-11-12T11:51:43.031+0000] {dagbag.py:525} INFO - Filling up the DagBag from /opt/***/dags/postgre_create_table.py
[2022-11-12T11:51:43.424+0000] {task_command.py:384} INFO - Running <TaskInstance: load_to_dwh_v2.load_raw_data manual__2022-11-12T11:51:30.115005+00:00 [running]> on host f73c12cbae8a
[2022-11-12T11:51:43.534+0000] {taskinstance.py:1592} INFO - Exporting the following env vars:
AIRFLOW_CTX_DAG_OWNER=nahom
AIRFLOW_CTX_DAG_ID=load_to_dwh_v2
AIRFLOW_CTX_TASK_ID=load_raw_data
AIRFLOW_CTX_EXECUTION_DATE=2022-11-12T11:51:30.115005+00:00
AIRFLOW_CTX_TRY_NUMBER=1
AIRFLOW_CTX_DAG_RUN_ID=manual__2022-11-12T11:51:30.115005+00:00
[2022-11-12T11:51:43.535+0000] {logging_mixin.py:117} INFO - writing data..............
[2022-11-12T11:51:43.537+0000] {taskinstance.py:1851} ERROR - Task failed with exception
Traceback (most recent call last):
  File "/home/airflow/.local/lib/python3.7/site-packages/airflow/operators/python.py", line 175, in execute
    return_value = self.execute_callable()
  File "/home/airflow/.local/lib/python3.7/site-packages/airflow/operators/python.py", line 193, in execute_callable
    return self.python_callable(*self.op_args, **self.op_kwargs)
  File "/opt/airflow/dags/postgre_create_table.py", line 20, in load_raw_data
    df = pd.read_csv(path, sep=",", index_col=False)
  File "/home/airflow/.local/lib/python3.7/site-packages/pandas/util/_decorators.py", line 311, in wrapper
    return func(*args, **kwargs)
  File "/home/airflow/.local/lib/python3.7/site-packages/pandas/io/parsers/readers.py", line 586, in read_csv
    return _read(filepath_or_buffer, kwds)
  File "/home/airflow/.local/lib/python3.7/site-packages/pandas/io/parsers/readers.py", line 482, in _read
    parser = TextFileReader(filepath_or_buffer, **kwds)
  File "/home/airflow/.local/lib/python3.7/site-packages/pandas/io/parsers/readers.py", line 811, in __init__
    self._engine = self._make_engine(self.engine)
  File "/home/airflow/.local/lib/python3.7/site-packages/pandas/io/parsers/readers.py", line 1040, in _make_engine
    return mapping[engine](self.f, **self.options)  # type: ignore[call-arg]
  File "/home/airflow/.local/lib/python3.7/site-packages/pandas/io/parsers/c_parser_wrapper.py", line 51, in __init__
    self._open_handles(src, kwds)
  File "/home/airflow/.local/lib/python3.7/site-packages/pandas/io/parsers/base_parser.py", line 229, in _open_handles
    errors=kwds.get("encoding_errors", "strict"),
  File "/home/airflow/.local/lib/python3.7/site-packages/pandas/io/common.py", line 707, in get_handle
    newline="",
FileNotFoundError: [Errno 2] No such file or directory: './data/cleanned_data.csv'
[2022-11-12T11:51:43.551+0000] {taskinstance.py:1406} INFO - Marking task as UP_FOR_RETRY. dag_id=load_to_dwh_v2, task_id=load_raw_data, execution_date=20221112T115130, start_date=20221112T115142, end_date=20221112T115143
[2022-11-12T11:51:43.569+0000] {standard_task_runner.py:107} ERROR - Failed to execute job 211 for task load_raw_data ([Errno 2] No such file or directory: './data/cleanned_data.csv'; 419)
[2022-11-12T11:51:43.605+0000] {local_task_job.py:164} INFO - Task exited with return code 1
[2022-11-12T11:51:43.646+0000] {local_task_job.py:273} INFO - 0 downstream tasks scheduled from follow-on schedule check
