[2022-11-12T11:30:24.634+0000] {taskinstance.py:1165} INFO - Dependencies all met for <TaskInstance: load_to_dwh_v2.extract_and_clean_data manual__2022-11-12T11:25:13.413009+00:00 [queued]>
[2022-11-12T11:30:24.646+0000] {taskinstance.py:1165} INFO - Dependencies all met for <TaskInstance: load_to_dwh_v2.extract_and_clean_data manual__2022-11-12T11:25:13.413009+00:00 [queued]>
[2022-11-12T11:30:24.646+0000] {taskinstance.py:1362} INFO - 
--------------------------------------------------------------------------------
[2022-11-12T11:30:24.646+0000] {taskinstance.py:1363} INFO - Starting attempt 3 of 6
[2022-11-12T11:30:24.646+0000] {taskinstance.py:1364} INFO - 
--------------------------------------------------------------------------------
[2022-11-12T11:30:24.660+0000] {taskinstance.py:1383} INFO - Executing <Task(PythonOperator): extract_and_clean_data> on 2022-11-12 11:25:13.413009+00:00
[2022-11-12T11:30:24.666+0000] {standard_task_runner.py:54} INFO - Started process 284 to run task
[2022-11-12T11:30:24.669+0000] {standard_task_runner.py:82} INFO - Running: ['***', 'tasks', 'run', 'load_to_dwh_v2', 'extract_and_clean_data', 'manual__2022-11-12T11:25:13.413009+00:00', '--job-id', '152', '--raw', '--subdir', 'DAGS_FOLDER/postgre_create_table.py', '--cfg-path', '/tmp/tmp6qrp1gue']
[2022-11-12T11:30:24.669+0000] {standard_task_runner.py:83} INFO - Job 152: Subtask extract_and_clean_data
[2022-11-12T11:30:24.670+0000] {dagbag.py:525} INFO - Filling up the DagBag from /opt/***/dags/postgre_create_table.py
[2022-11-12T11:30:24.976+0000] {task_command.py:384} INFO - Running <TaskInstance: load_to_dwh_v2.extract_and_clean_data manual__2022-11-12T11:25:13.413009+00:00 [running]> on host f73c12cbae8a
[2022-11-12T11:30:25.041+0000] {taskinstance.py:1592} INFO - Exporting the following env vars:
AIRFLOW_CTX_DAG_OWNER=nahom
AIRFLOW_CTX_DAG_ID=load_to_dwh_v2
AIRFLOW_CTX_TASK_ID=extract_and_clean_data
AIRFLOW_CTX_EXECUTION_DATE=2022-11-12T11:25:13.413009+00:00
AIRFLOW_CTX_TRY_NUMBER=3
AIRFLOW_CTX_DAG_RUN_ID=manual__2022-11-12T11:25:13.413009+00:00
[2022-11-12T11:30:25.042+0000] {warnings.py:110} WARNING - /home/***/.local/lib/python3.7/site-packages/pandas/util/_decorators.py:311: ParserWarning: Falling back to the 'python' engine because the 'c' engine does not support regex separators (separators > 1 char and different from '\s+' are interpreted as regex); you can avoid this warning by specifying engine='python'.
  return func(*args, **kwargs)

[2022-11-12T11:30:32.396+0000] {warnings.py:110} WARNING - /home/***/.local/lib/python3.7/site-packages/pandas/io/parsers/readers.py:586: ParserWarning: Length of header or names does not match length of data. This leads to a loss of data with index_col=False.
  return _read(filepath_or_buffer, kwds)

[2022-11-12T11:30:34.454+0000] {taskinstance.py:1851} ERROR - Task failed with exception
Traceback (most recent call last):
  File "/home/airflow/.local/lib/python3.7/site-packages/airflow/operators/python.py", line 175, in execute
    return_value = self.execute_callable()
  File "/home/airflow/.local/lib/python3.7/site-packages/airflow/operators/python.py", line 193, in execute_callable
    return self.python_callable(*self.op_args, **self.op_kwargs)
  File "/opt/airflow/dags/postgre_create_table.py", line 28, in clean_df
    df.to_csv('./data/cleanned_data.csv',index=False)
  File "/home/airflow/.local/lib/python3.7/site-packages/pandas/core/generic.py", line 3482, in to_csv
    storage_options=storage_options,
  File "/home/airflow/.local/lib/python3.7/site-packages/pandas/io/formats/format.py", line 1105, in to_csv
    csv_formatter.save()
  File "/home/airflow/.local/lib/python3.7/site-packages/pandas/io/formats/csvs.py", line 243, in save
    storage_options=self.storage_options,
  File "/home/airflow/.local/lib/python3.7/site-packages/pandas/io/common.py", line 707, in get_handle
    newline="",
PermissionError: [Errno 13] Permission denied: './data/cleanned_data.csv'
[2022-11-12T11:30:34.470+0000] {taskinstance.py:1406} INFO - Marking task as UP_FOR_RETRY. dag_id=load_to_dwh_v2, task_id=extract_and_clean_data, execution_date=20221112T112513, start_date=20221112T113024, end_date=20221112T113034
[2022-11-12T11:30:34.496+0000] {standard_task_runner.py:107} ERROR - Failed to execute job 152 for task extract_and_clean_data ([Errno 13] Permission denied: './data/cleanned_data.csv'; 284)
[2022-11-12T11:30:34.566+0000] {local_task_job.py:164} INFO - Task exited with return code 1
[2022-11-12T11:30:34.612+0000] {local_task_job.py:273} INFO - 0 downstream tasks scheduled from follow-on schedule check
