[2022-11-12T11:34:34.674+0000] {taskinstance.py:1165} INFO - Dependencies all met for <TaskInstance: load_to_dwh_v2.extract_and_clean_data manual__2022-11-12T11:26:37.620584+00:00 [queued]>
[2022-11-12T11:34:34.686+0000] {taskinstance.py:1165} INFO - Dependencies all met for <TaskInstance: load_to_dwh_v2.extract_and_clean_data manual__2022-11-12T11:26:37.620584+00:00 [queued]>
[2022-11-12T11:34:34.686+0000] {taskinstance.py:1362} INFO - 
--------------------------------------------------------------------------------
[2022-11-12T11:34:34.686+0000] {taskinstance.py:1363} INFO - Starting attempt 4 of 6
[2022-11-12T11:34:34.686+0000] {taskinstance.py:1364} INFO - 
--------------------------------------------------------------------------------
[2022-11-12T11:34:34.702+0000] {taskinstance.py:1383} INFO - Executing <Task(PythonOperator): extract_and_clean_data> on 2022-11-12 11:26:37.620584+00:00
[2022-11-12T11:34:34.708+0000] {standard_task_runner.py:54} INFO - Started process 493 to run task
[2022-11-12T11:34:34.712+0000] {standard_task_runner.py:82} INFO - Running: ['***', 'tasks', 'run', 'load_to_dwh_v2', 'extract_and_clean_data', 'manual__2022-11-12T11:26:37.620584+00:00', '--job-id', '158', '--raw', '--subdir', 'DAGS_FOLDER/postgre_create_table.py', '--cfg-path', '/tmp/tmpb9erdpb0']
[2022-11-12T11:34:34.713+0000] {standard_task_runner.py:83} INFO - Job 158: Subtask extract_and_clean_data
[2022-11-12T11:34:34.713+0000] {dagbag.py:525} INFO - Filling up the DagBag from /opt/***/dags/postgre_create_table.py
[2022-11-12T11:34:34.716+0000] {dagbag.py:330} ERROR - Failed to import: /opt/***/dags/postgre_create_table.py
Traceback (most recent call last):
  File "/home/airflow/.local/lib/python3.7/site-packages/airflow/models/dagbag.py", line 326, in parse
    loader.exec_module(new_module)
  File "<frozen importlib._bootstrap_external>", line 728, in exec_module
  File "<frozen importlib._bootstrap>", line 219, in _call_with_frames_removed
  File "/opt/airflow/dags/postgre_create_table.py", line 6, in <module>
    sys.path.append(os.path.abspath(".."))
NameError: name 'sys' is not defined
[2022-11-12T11:34:34.718+0000] {standard_task_runner.py:107} ERROR - Failed to execute job 158 for task extract_and_clean_data (Dag 'load_to_dwh_v2' could not be found; either it does not exist or it failed to parse.; 493)
[2022-11-12T11:34:34.737+0000] {local_task_job.py:164} INFO - Task exited with return code 1
[2022-11-12T11:34:34.773+0000] {local_task_job.py:273} INFO - 0 downstream tasks scheduled from follow-on schedule check
