[2022-09-22T06:11:48.544+0000] {taskinstance.py:1165} INFO - Dependencies all met for <TaskInstance: postgres_operator_dag.create_table scheduled__2022-09-22T02:15:00+00:00 [queued]>
[2022-09-22T06:11:48.559+0000] {taskinstance.py:1165} INFO - Dependencies all met for <TaskInstance: postgres_operator_dag.create_table scheduled__2022-09-22T02:15:00+00:00 [queued]>
[2022-09-22T06:11:48.559+0000] {taskinstance.py:1362} INFO - 
--------------------------------------------------------------------------------
[2022-09-22T06:11:48.559+0000] {taskinstance.py:1363} INFO - Starting attempt 2 of 6
[2022-09-22T06:11:48.560+0000] {taskinstance.py:1364} INFO - 
--------------------------------------------------------------------------------
[2022-09-22T06:11:48.582+0000] {taskinstance.py:1383} INFO - Executing <Task(PythonOperator): create_table> on 2022-09-22 02:15:00+00:00
[2022-09-22T06:11:48.586+0000] {standard_task_runner.py:54} INFO - Started process 111 to run task
[2022-09-22T06:11:48.590+0000] {standard_task_runner.py:82} INFO - Running: ['***', 'tasks', 'run', 'postgres_operator_dag', 'create_table', 'scheduled__2022-09-22T02:15:00+00:00', '--job-id', '42', '--raw', '--subdir', 'DAGS_FOLDER/postgre_create_table.py', '--cfg-path', '/tmp/tmpiitbnex3']
[2022-09-22T06:11:48.590+0000] {standard_task_runner.py:83} INFO - Job 42: Subtask create_table
[2022-09-22T06:11:48.591+0000] {dagbag.py:525} INFO - Filling up the DagBag from /opt/***/dags/postgre_create_table.py
[2022-09-22T06:11:49.116+0000] {task_command.py:384} INFO - Running <TaskInstance: postgres_operator_dag.create_table scheduled__2022-09-22T02:15:00+00:00 [running]> on host 77dc7c74a950
[2022-09-22T06:11:49.226+0000] {taskinstance.py:1592} INFO - Exporting the following env vars:
AIRFLOW_CTX_DAG_OWNER=***
AIRFLOW_CTX_DAG_ID=postgres_operator_dag
AIRFLOW_CTX_TASK_ID=create_table
AIRFLOW_CTX_EXECUTION_DATE=2022-09-22T02:15:00+00:00
AIRFLOW_CTX_TRY_NUMBER=2
AIRFLOW_CTX_DAG_RUN_ID=scheduled__2022-09-22T02:15:00+00:00
[2022-09-22T06:11:49.227+0000] {logging_mixin.py:117} INFO - writing.............
[2022-09-22T06:11:49.229+0000] {taskinstance.py:1851} ERROR - Task failed with exception
Traceback (most recent call last):
  File "/home/airflow/.local/lib/python3.7/site-packages/airflow/operators/python.py", line 175, in execute
    return_value = self.execute_callable()
  File "/home/airflow/.local/lib/python3.7/site-packages/airflow/operators/python.py", line 193, in execute_callable
    return self.python_callable(*self.op_args, **self.op_kwargs)
  File "/opt/airflow/dags/postgre_create_table.py", line 16, in load_data
    df = pd.read_csv(path,index_col=False, low_memory=False)
  File "/home/airflow/.local/lib/python3.7/site-packages/pandas/util/_decorators.py", line 311, in wrapper
    return func(*args, **kwargs)
  File "/home/airflow/.local/lib/python3.7/site-packages/pandas/io/parsers/readers.py", line 586, in read_csv
    return _read(filepath_or_buffer, kwds)
  File "/home/airflow/.local/lib/python3.7/site-packages/pandas/io/parsers/readers.py", line 482, in _read
    parser = TextFileReader(filepath_or_buffer, **kwds)
  File "/home/airflow/.local/lib/python3.7/site-packages/pandas/io/parsers/readers.py", line 811, in __init__
    self._engine = self._make_engine(self.engine)
  File "/home/airflow/.local/lib/python3.7/site-packages/pandas/io/parsers/readers.py", line 1040, in _make_engine
    return mapping[engine](self.f, **self.options)  # type: ignore[call-arg]
  File "/home/airflow/.local/lib/python3.7/site-packages/pandas/io/parsers/c_parser_wrapper.py", line 51, in __init__
    self._open_handles(src, kwds)
  File "/home/airflow/.local/lib/python3.7/site-packages/pandas/io/parsers/base_parser.py", line 229, in _open_handles
    errors=kwds.get("encoding_errors", "strict"),
  File "/home/airflow/.local/lib/python3.7/site-packages/pandas/io/common.py", line 707, in get_handle
    newline="",
FileNotFoundError: [Errno 2] No such file or directory: './data/drone3_clean.csv'
[2022-09-22T06:11:49.241+0000] {taskinstance.py:1406} INFO - Marking task as UP_FOR_RETRY. dag_id=postgres_operator_dag, task_id=create_table, execution_date=20220922T021500, start_date=20220922T061148, end_date=20220922T061149
[2022-09-22T06:11:49.259+0000] {standard_task_runner.py:107} ERROR - Failed to execute job 42 for task create_table ([Errno 2] No such file or directory: './data/drone3_clean.csv'; 111)
[2022-09-22T06:11:49.282+0000] {local_task_job.py:164} INFO - Task exited with return code 1
[2022-09-22T06:11:49.314+0000] {local_task_job.py:273} INFO - 0 downstream tasks scheduled from follow-on schedule check
