[2022-11-14 11:18:13,867] {taskinstance.py:1035} INFO - Dependencies all met for <TaskInstance: dbt_dag.dbt_run manual__2022-11-14T11:18:12.005533+00:00 [queued]>
[2022-11-14 11:18:13,886] {taskinstance.py:1035} INFO - Dependencies all met for <TaskInstance: dbt_dag.dbt_run manual__2022-11-14T11:18:12.005533+00:00 [queued]>
[2022-11-14 11:18:13,886] {taskinstance.py:1241} INFO - 
--------------------------------------------------------------------------------
[2022-11-14 11:18:13,886] {taskinstance.py:1242} INFO - Starting attempt 1 of 1
[2022-11-14 11:18:13,886] {taskinstance.py:1243} INFO - 
--------------------------------------------------------------------------------
[2022-11-14 11:18:13,913] {taskinstance.py:1262} INFO - Executing <Task(BashOperator): dbt_run> on 2022-11-14 11:18:12.005533+00:00
[2022-11-14 11:18:13,924] {standard_task_runner.py:76} INFO - Running: ['***', 'tasks', 'run', 'dbt_dag', 'dbt_run', 'manual__2022-11-14T11:18:12.005533+00:00', '--job-id', '307', '--raw', '--subdir', 'DAGS_FOLDER/dbt_transform.py', '--cfg-path', '/tmp/tmp2wxmz0gz', '--error-file', '/tmp/tmp0awuysv9']
[2022-11-14 11:18:13,919] {standard_task_runner.py:52} INFO - Started process 150 to run task
[2022-11-14 11:18:13,925] {standard_task_runner.py:77} INFO - Job 307: Subtask dbt_run
[2022-11-14 11:18:13,985] {logging_mixin.py:109} INFO - Running <TaskInstance: dbt_dag.dbt_run manual__2022-11-14T11:18:12.005533+00:00 [running]> on host b1d920162f4e
[2022-11-14 11:18:14,024] {taskinstance.py:1686} ERROR - Task failed with exception
Traceback (most recent call last):
  File "/home/airflow/.local/lib/python3.6/site-packages/sqlalchemy/engine/base.py", line 1277, in _execute_context
    cursor, statement, parameters, context
  File "/home/airflow/.local/lib/python3.6/site-packages/sqlalchemy/engine/default.py", line 608, in do_execute
    cursor.execute(statement, parameters)
psycopg2.errors.UndefinedColumn: column xcom.execution_date does not exist
LINE 1: ...g_id = 'dbt_dag' AND xcom.task_id = 'dbt_run' AND xcom.execu...
                                                             ^


The above exception was the direct cause of the following exception:

Traceback (most recent call last):
  File "/home/airflow/.local/lib/python3.6/site-packages/airflow/models/taskinstance.py", line 1324, in _run_raw_task
    self._execute_task_with_callbacks(context)
  File "/home/airflow/.local/lib/python3.6/site-packages/airflow/models/taskinstance.py", line 1403, in _execute_task_with_callbacks
    self.clear_xcom_data()
  File "/home/airflow/.local/lib/python3.6/site-packages/airflow/utils/session.py", line 70, in wrapper
    return func(*args, session=session, **kwargs)
  File "/home/airflow/.local/lib/python3.6/site-packages/airflow/models/taskinstance.py", line 795, in clear_xcom_data
    session=session,
  File "/home/airflow/.local/lib/python3.6/site-packages/airflow/utils/session.py", line 67, in wrapper
    return func(*args, **kwargs)
  File "/home/airflow/.local/lib/python3.6/site-packages/airflow/models/xcom.py", line 322, in clear
    return query.delete()
  File "/home/airflow/.local/lib/python3.6/site-packages/sqlalchemy/orm/query.py", line 3926, in delete
    delete_op.exec_()
  File "/home/airflow/.local/lib/python3.6/site-packages/sqlalchemy/orm/persistence.py", line 1697, in exec_
    self._do_exec()
  File "/home/airflow/.local/lib/python3.6/site-packages/sqlalchemy/orm/persistence.py", line 1930, in _do_exec
    self._execute_stmt(delete_stmt)
  File "/home/airflow/.local/lib/python3.6/site-packages/sqlalchemy/orm/persistence.py", line 1702, in _execute_stmt
    self.result = self.query._execute_crud(stmt, self.mapper)
  File "/home/airflow/.local/lib/python3.6/site-packages/sqlalchemy/orm/query.py", line 3568, in _execute_crud
    return conn.execute(stmt, self._params)
  File "/home/airflow/.local/lib/python3.6/site-packages/sqlalchemy/engine/base.py", line 1011, in execute
    return meth(self, multiparams, params)
  File "/home/airflow/.local/lib/python3.6/site-packages/sqlalchemy/sql/elements.py", line 298, in _execute_on_connection
    return connection._execute_clauseelement(self, multiparams, params)
  File "/home/airflow/.local/lib/python3.6/site-packages/sqlalchemy/engine/base.py", line 1130, in _execute_clauseelement
    distilled_params,
  File "/home/airflow/.local/lib/python3.6/site-packages/sqlalchemy/engine/base.py", line 1317, in _execute_context
    e, statement, parameters, cursor, context
  File "/home/airflow/.local/lib/python3.6/site-packages/sqlalchemy/engine/base.py", line 1511, in _handle_dbapi_exception
    sqlalchemy_exception, with_traceback=exc_info[2], from_=e
  File "/home/airflow/.local/lib/python3.6/site-packages/sqlalchemy/util/compat.py", line 182, in raise_
    raise exception
  File "/home/airflow/.local/lib/python3.6/site-packages/sqlalchemy/engine/base.py", line 1277, in _execute_context
    cursor, statement, parameters, context
  File "/home/airflow/.local/lib/python3.6/site-packages/sqlalchemy/engine/default.py", line 608, in do_execute
    cursor.execute(statement, parameters)
sqlalchemy.exc.ProgrammingError: (psycopg2.errors.UndefinedColumn) column xcom.execution_date does not exist
LINE 1: ...g_id = 'dbt_dag' AND xcom.task_id = 'dbt_run' AND xcom.execu...
                                                             ^

[SQL: DELETE FROM xcom WHERE xcom.dag_id = %(dag_id_1)s AND xcom.task_id = %(task_id_1)s AND xcom.execution_date = %(execution_date_1)s]
[parameters: {'dag_id_1': 'dbt_dag', 'task_id_1': 'dbt_run', 'execution_date_1': datetime.datetime(2022, 11, 14, 11, 18, 12, 5533, tzinfo=Timezone('UTC'))}]
(Background on this error at: http://sqlalche.me/e/13/f405)
[2022-11-14 11:18:14,060] {taskinstance.py:1280} INFO - Marking task as FAILED. dag_id=dbt_dag, task_id=dbt_run, execution_date=20221114T111812, start_date=20221114T111813, end_date=20221114T111814
[2022-11-14 11:18:14,088] {warnings.py:99} WARNING - /home/***/.local/lib/python3.6/site-packages/***/utils/email.py:102: PendingDeprecationWarning: Fetching SMTP credentials from configuration variables will be deprecated in a future release. Please set credentials using a connection instead.
  send_mime_email(e_from=smtp_mail_from, e_to=recipients, mime_msg=msg, conn_id=conn_id, dryrun=dryrun)

[2022-11-14 11:18:14,088] {configuration.py:381} WARNING - section/key [smtp/smtp_user] not found in config
[2022-11-14 11:18:14,088] {email.py:208} INFO - Email alerting: attempt 1
[2022-11-14 11:18:14,102] {configuration.py:381} WARNING - section/key [smtp/smtp_user] not found in config
[2022-11-14 11:18:14,102] {email.py:208} INFO - Email alerting: attempt 1
[2022-11-14 11:18:14,103] {taskinstance.py:1739} ERROR - Failed to send email to: ['natnaelmasresha@gmail.com']
Traceback (most recent call last):
  File "/home/airflow/.local/lib/python3.6/site-packages/sqlalchemy/engine/base.py", line 1277, in _execute_context
    cursor, statement, parameters, context
  File "/home/airflow/.local/lib/python3.6/site-packages/sqlalchemy/engine/default.py", line 608, in do_execute
    cursor.execute(statement, parameters)
psycopg2.errors.UndefinedColumn: column xcom.execution_date does not exist
LINE 1: ...g_id = 'dbt_dag' AND xcom.task_id = 'dbt_run' AND xcom.execu...
                                                             ^


The above exception was the direct cause of the following exception:

Traceback (most recent call last):
  File "/home/airflow/.local/lib/python3.6/site-packages/airflow/models/taskinstance.py", line 1324, in _run_raw_task
    self._execute_task_with_callbacks(context)
  File "/home/airflow/.local/lib/python3.6/site-packages/airflow/models/taskinstance.py", line 1403, in _execute_task_with_callbacks
    self.clear_xcom_data()
  File "/home/airflow/.local/lib/python3.6/site-packages/airflow/utils/session.py", line 70, in wrapper
    return func(*args, session=session, **kwargs)
  File "/home/airflow/.local/lib/python3.6/site-packages/airflow/models/taskinstance.py", line 795, in clear_xcom_data
    session=session,
  File "/home/airflow/.local/lib/python3.6/site-packages/airflow/utils/session.py", line 67, in wrapper
    return func(*args, **kwargs)
  File "/home/airflow/.local/lib/python3.6/site-packages/airflow/models/xcom.py", line 322, in clear
    return query.delete()
  File "/home/airflow/.local/lib/python3.6/site-packages/sqlalchemy/orm/query.py", line 3926, in delete
    delete_op.exec_()
  File "/home/airflow/.local/lib/python3.6/site-packages/sqlalchemy/orm/persistence.py", line 1697, in exec_
    self._do_exec()
  File "/home/airflow/.local/lib/python3.6/site-packages/sqlalchemy/orm/persistence.py", line 1930, in _do_exec
    self._execute_stmt(delete_stmt)
  File "/home/airflow/.local/lib/python3.6/site-packages/sqlalchemy/orm/persistence.py", line 1702, in _execute_stmt
    self.result = self.query._execute_crud(stmt, self.mapper)
  File "/home/airflow/.local/lib/python3.6/site-packages/sqlalchemy/orm/query.py", line 3568, in _execute_crud
    return conn.execute(stmt, self._params)
  File "/home/airflow/.local/lib/python3.6/site-packages/sqlalchemy/engine/base.py", line 1011, in execute
    return meth(self, multiparams, params)
  File "/home/airflow/.local/lib/python3.6/site-packages/sqlalchemy/sql/elements.py", line 298, in _execute_on_connection
    return connection._execute_clauseelement(self, multiparams, params)
  File "/home/airflow/.local/lib/python3.6/site-packages/sqlalchemy/engine/base.py", line 1130, in _execute_clauseelement
    distilled_params,
  File "/home/airflow/.local/lib/python3.6/site-packages/sqlalchemy/engine/base.py", line 1317, in _execute_context
    e, statement, parameters, cursor, context
  File "/home/airflow/.local/lib/python3.6/site-packages/sqlalchemy/engine/base.py", line 1511, in _handle_dbapi_exception
    sqlalchemy_exception, with_traceback=exc_info[2], from_=e
  File "/home/airflow/.local/lib/python3.6/site-packages/sqlalchemy/util/compat.py", line 182, in raise_
    raise exception
  File "/home/airflow/.local/lib/python3.6/site-packages/sqlalchemy/engine/base.py", line 1277, in _execute_context
    cursor, statement, parameters, context
  File "/home/airflow/.local/lib/python3.6/site-packages/sqlalchemy/engine/default.py", line 608, in do_execute
    cursor.execute(statement, parameters)
sqlalchemy.exc.ProgrammingError: (psycopg2.errors.UndefinedColumn) column xcom.execution_date does not exist
LINE 1: ...g_id = 'dbt_dag' AND xcom.task_id = 'dbt_run' AND xcom.execu...
                                                             ^

[SQL: DELETE FROM xcom WHERE xcom.dag_id = %(dag_id_1)s AND xcom.task_id = %(task_id_1)s AND xcom.execution_date = %(execution_date_1)s]
[parameters: {'dag_id_1': 'dbt_dag', 'task_id_1': 'dbt_run', 'execution_date_1': datetime.datetime(2022, 11, 14, 11, 18, 12, 5533, tzinfo=Timezone('UTC'))}]
(Background on this error at: http://sqlalche.me/e/13/f405)

During handling of the above exception, another exception occurred:

Traceback (most recent call last):
  File "/home/airflow/.local/lib/python3.6/site-packages/airflow/models/taskinstance.py", line 2189, in email_alert
    send_email(self.task.email, subject, html_content)
  File "/home/airflow/.local/lib/python3.6/site-packages/airflow/utils/email.py", line 66, in send_email
    **kwargs,
  File "/home/airflow/.local/lib/python3.6/site-packages/airflow/utils/email.py", line 102, in send_email_smtp
    send_mime_email(e_from=smtp_mail_from, e_to=recipients, mime_msg=msg, conn_id=conn_id, dryrun=dryrun)
  File "/home/airflow/.local/lib/python3.6/site-packages/airflow/utils/email.py", line 210, in send_mime_email
    conn = _get_smtp_connection(smtp_host, smtp_port, smtp_timeout, smtp_ssl)
  File "/home/airflow/.local/lib/python3.6/site-packages/airflow/utils/email.py", line 244, in _get_smtp_connection
    else smtplib.SMTP(host=host, port=port, timeout=timeout)
  File "/usr/local/lib/python3.6/smtplib.py", line 251, in __init__
    (code, msg) = self.connect(host, port)
  File "/usr/local/lib/python3.6/smtplib.py", line 336, in connect
    self.sock = self._get_socket(host, port, self.timeout)
  File "/usr/local/lib/python3.6/smtplib.py", line 307, in _get_socket
    self.source_address)
  File "/usr/local/lib/python3.6/socket.py", line 724, in create_connection
    raise err
  File "/usr/local/lib/python3.6/socket.py", line 713, in create_connection
    sock.connect(sa)
OSError: [Errno 99] Cannot assign requested address

During handling of the above exception, another exception occurred:

Traceback (most recent call last):
  File "/home/airflow/.local/lib/python3.6/site-packages/airflow/models/taskinstance.py", line 1737, in handle_failure
    self.email_alert(error)
  File "/home/airflow/.local/lib/python3.6/site-packages/airflow/models/taskinstance.py", line 2191, in email_alert
    send_email(self.task.email, subject, html_content_err)
  File "/home/airflow/.local/lib/python3.6/site-packages/airflow/utils/email.py", line 66, in send_email
    **kwargs,
  File "/home/airflow/.local/lib/python3.6/site-packages/airflow/utils/email.py", line 102, in send_email_smtp
    send_mime_email(e_from=smtp_mail_from, e_to=recipients, mime_msg=msg, conn_id=conn_id, dryrun=dryrun)
  File "/home/airflow/.local/lib/python3.6/site-packages/airflow/utils/email.py", line 210, in send_mime_email
    conn = _get_smtp_connection(smtp_host, smtp_port, smtp_timeout, smtp_ssl)
  File "/home/airflow/.local/lib/python3.6/site-packages/airflow/utils/email.py", line 244, in _get_smtp_connection
    else smtplib.SMTP(host=host, port=port, timeout=timeout)
  File "/usr/local/lib/python3.6/smtplib.py", line 251, in __init__
    (code, msg) = self.connect(host, port)
  File "/usr/local/lib/python3.6/smtplib.py", line 336, in connect
    self.sock = self._get_socket(host, port, self.timeout)
  File "/usr/local/lib/python3.6/smtplib.py", line 307, in _get_socket
    self.source_address)
  File "/usr/local/lib/python3.6/socket.py", line 724, in create_connection
    raise err
  File "/usr/local/lib/python3.6/socket.py", line 713, in create_connection
    sock.connect(sa)
OSError: [Errno 99] Cannot assign requested address
[2022-11-14 11:18:14,131] {standard_task_runner.py:91} ERROR - Failed to execute job 307 for task dbt_run
Traceback (most recent call last):
  File "/home/airflow/.local/lib/python3.6/site-packages/sqlalchemy/engine/base.py", line 1277, in _execute_context
    cursor, statement, parameters, context
  File "/home/airflow/.local/lib/python3.6/site-packages/sqlalchemy/engine/default.py", line 608, in do_execute
    cursor.execute(statement, parameters)
psycopg2.errors.UndefinedColumn: column xcom.execution_date does not exist
LINE 1: ...g_id = 'dbt_dag' AND xcom.task_id = 'dbt_run' AND xcom.execu...
                                                             ^


The above exception was the direct cause of the following exception:

Traceback (most recent call last):
  File "/home/airflow/.local/lib/python3.6/site-packages/airflow/task/task_runner/standard_task_runner.py", line 85, in _start_by_fork
    args.func(args, dag=self.dag)
  File "/home/airflow/.local/lib/python3.6/site-packages/airflow/cli/cli_parser.py", line 48, in command
    return func(*args, **kwargs)
  File "/home/airflow/.local/lib/python3.6/site-packages/airflow/utils/cli.py", line 92, in wrapper
    return f(*args, **kwargs)
  File "/home/airflow/.local/lib/python3.6/site-packages/airflow/cli/commands/task_command.py", line 292, in task_run
    _run_task_by_selected_method(args, dag, ti)
  File "/home/airflow/.local/lib/python3.6/site-packages/airflow/cli/commands/task_command.py", line 107, in _run_task_by_selected_method
    _run_raw_task(args, ti)
  File "/home/airflow/.local/lib/python3.6/site-packages/airflow/cli/commands/task_command.py", line 184, in _run_raw_task
    error_file=args.error_file,
  File "/home/airflow/.local/lib/python3.6/site-packages/airflow/utils/session.py", line 70, in wrapper
    return func(*args, session=session, **kwargs)
  File "/home/airflow/.local/lib/python3.6/site-packages/airflow/models/taskinstance.py", line 1324, in _run_raw_task
    self._execute_task_with_callbacks(context)
  File "/home/airflow/.local/lib/python3.6/site-packages/airflow/models/taskinstance.py", line 1403, in _execute_task_with_callbacks
    self.clear_xcom_data()
  File "/home/airflow/.local/lib/python3.6/site-packages/airflow/utils/session.py", line 70, in wrapper
    return func(*args, session=session, **kwargs)
  File "/home/airflow/.local/lib/python3.6/site-packages/airflow/models/taskinstance.py", line 795, in clear_xcom_data
    session=session,
  File "/home/airflow/.local/lib/python3.6/site-packages/airflow/utils/session.py", line 67, in wrapper
    return func(*args, **kwargs)
  File "/home/airflow/.local/lib/python3.6/site-packages/airflow/models/xcom.py", line 322, in clear
    return query.delete()
  File "/home/airflow/.local/lib/python3.6/site-packages/sqlalchemy/orm/query.py", line 3926, in delete
    delete_op.exec_()
  File "/home/airflow/.local/lib/python3.6/site-packages/sqlalchemy/orm/persistence.py", line 1697, in exec_
    self._do_exec()
  File "/home/airflow/.local/lib/python3.6/site-packages/sqlalchemy/orm/persistence.py", line 1930, in _do_exec
    self._execute_stmt(delete_stmt)
  File "/home/airflow/.local/lib/python3.6/site-packages/sqlalchemy/orm/persistence.py", line 1702, in _execute_stmt
    self.result = self.query._execute_crud(stmt, self.mapper)
  File "/home/airflow/.local/lib/python3.6/site-packages/sqlalchemy/orm/query.py", line 3568, in _execute_crud
    return conn.execute(stmt, self._params)
  File "/home/airflow/.local/lib/python3.6/site-packages/sqlalchemy/engine/base.py", line 1011, in execute
    return meth(self, multiparams, params)
  File "/home/airflow/.local/lib/python3.6/site-packages/sqlalchemy/sql/elements.py", line 298, in _execute_on_connection
    return connection._execute_clauseelement(self, multiparams, params)
  File "/home/airflow/.local/lib/python3.6/site-packages/sqlalchemy/engine/base.py", line 1130, in _execute_clauseelement
    distilled_params,
  File "/home/airflow/.local/lib/python3.6/site-packages/sqlalchemy/engine/base.py", line 1317, in _execute_context
    e, statement, parameters, cursor, context
  File "/home/airflow/.local/lib/python3.6/site-packages/sqlalchemy/engine/base.py", line 1511, in _handle_dbapi_exception
    sqlalchemy_exception, with_traceback=exc_info[2], from_=e
  File "/home/airflow/.local/lib/python3.6/site-packages/sqlalchemy/util/compat.py", line 182, in raise_
    raise exception
  File "/home/airflow/.local/lib/python3.6/site-packages/sqlalchemy/engine/base.py", line 1277, in _execute_context
    cursor, statement, parameters, context
  File "/home/airflow/.local/lib/python3.6/site-packages/sqlalchemy/engine/default.py", line 608, in do_execute
    cursor.execute(statement, parameters)
sqlalchemy.exc.ProgrammingError: (psycopg2.errors.UndefinedColumn) column xcom.execution_date does not exist
LINE 1: ...g_id = 'dbt_dag' AND xcom.task_id = 'dbt_run' AND xcom.execu...
                                                             ^

[SQL: DELETE FROM xcom WHERE xcom.dag_id = %(dag_id_1)s AND xcom.task_id = %(task_id_1)s AND xcom.execution_date = %(execution_date_1)s]
[parameters: {'dag_id_1': 'dbt_dag', 'task_id_1': 'dbt_run', 'execution_date_1': datetime.datetime(2022, 11, 14, 11, 18, 12, 5533, tzinfo=Timezone('UTC'))}]
(Background on this error at: http://sqlalche.me/e/13/f405)
[2022-11-14 11:18:14,145] {local_task_job.py:154} INFO - Task exited with return code 1
[2022-11-14 11:18:14,230] {local_task_job.py:264} INFO - 0 downstream tasks scheduled from follow-on schedule check
